Traceback (most recent call last):
  File "/opt/hostedtoolcache/Python/3.8.12/x64/lib/python3.8/site-packages/jupyter_cache/executors/utils.py", line 51, in single_nb_execution
    executenb(
  File "/opt/hostedtoolcache/Python/3.8.12/x64/lib/python3.8/site-packages/nbclient/client.py", line 1117, in execute
    return NotebookClient(nb=nb, resources=resources, km=km, **kwargs).execute()
  File "/opt/hostedtoolcache/Python/3.8.12/x64/lib/python3.8/site-packages/nbclient/util.py", line 78, in wrapped
    return just_run(coro(*args, **kwargs))
  File "/opt/hostedtoolcache/Python/3.8.12/x64/lib/python3.8/site-packages/nbclient/util.py", line 57, in just_run
    return loop.run_until_complete(coro)
  File "/opt/hostedtoolcache/Python/3.8.12/x64/lib/python3.8/asyncio/base_events.py", line 616, in run_until_complete
    return future.result()
  File "/opt/hostedtoolcache/Python/3.8.12/x64/lib/python3.8/site-packages/nbclient/client.py", line 558, in async_execute
    await self.async_execute_cell(
  File "/opt/hostedtoolcache/Python/3.8.12/x64/lib/python3.8/site-packages/nbclient/client.py", line 862, in async_execute_cell
    self._check_raise_for_error(cell, exec_reply)
  File "/opt/hostedtoolcache/Python/3.8.12/x64/lib/python3.8/site-packages/nbclient/client.py", line 765, in _check_raise_for_error
    raise CellExecutionError.from_cell_and_msg(cell, exec_reply_content)
nbclient.exceptions.CellExecutionError: An error occurred while executing the following cell:
------------------
import original.T1_mapping.MJT_EdinburghUK.t1 as edinburgh
import original.T1_mapping.ST_SydneyAus.VFAT1mapping as sydney
import original.T1_mapping.McGill.vfa as mcgill
import matplotlib.pyplot as plt
import os
import json
import re
import urllib.request
import nibabel as nib
import mat73
import numpy as np
from numpy.linalg import norm

plt.style.use('https://gist.github.com/notZaki/8bfb049230e307f4432fd68d24c603a1/raw/c0baa2a1c55afdf1764b26ee2ebeb1cbf26d8d98/pltstyle')
------------------

[0;31m---------------------------------------------------------------------------[0m
[0;31mModuleNotFoundError[0m                       Traceback (most recent call last)
[0;32m/tmp/ipykernel_1893/3717574537.py[0m in [0;36m<module>[0;34m[0m
[0;32m----> 1[0;31m [0;32mimport[0m [0moriginal[0m[0;34m.[0m[0mT1_mapping[0m[0;34m.[0m[0mMJT_EdinburghUK[0m[0;34m.[0m[0mt1[0m [0;32mas[0m [0medinburgh[0m[0;34m[0m[0;34m[0m[0m
[0m[1;32m      2[0m [0;32mimport[0m [0moriginal[0m[0;34m.[0m[0mT1_mapping[0m[0;34m.[0m[0mST_SydneyAus[0m[0;34m.[0m[0mVFAT1mapping[0m [0;32mas[0m [0msydney[0m[0;34m[0m[0;34m[0m[0m
[1;32m      3[0m [0;32mimport[0m [0moriginal[0m[0;34m.[0m[0mT1_mapping[0m[0;34m.[0m[0mMcGill[0m[0;34m.[0m[0mvfa[0m [0;32mas[0m [0mmcgill[0m[0;34m[0m[0;34m[0m[0m
[1;32m      4[0m [0;32mimport[0m [0mmatplotlib[0m[0;34m.[0m[0mpyplot[0m [0;32mas[0m [0mplt[0m[0;34m[0m[0;34m[0m[0m
[1;32m      5[0m [0;32mimport[0m [0mos[0m[0;34m[0m[0;34m[0m[0m

[0;31mModuleNotFoundError[0m: No module named 'original.T1_mapping.MJT_EdinburghUK'
ModuleNotFoundError: No module named 'original.T1_mapping.MJT_EdinburghUK'

